Workbook

Sheet Base de vendas
A1: Cliente | B1: Vendedor | C1: Categoria | D1: Detalhe | E1: Número de série da venda | F1: Valor de venda | G1: Valor anterior | H1: Número de série da venda limpo | I1: Efetivação de recebimento | J1: Verificação de vendas efetuadas | K1: Comissão dos Vendedores | L1: Comissão dos Vendedores TOTAL | M1: Data de pagamento Comissão aos vendedores | N1: Comissão do Backoffice | O1: TOTAL Backoffice | P1: TOTAL | Q1: DATA DE PAGAMENTO BACKOFFICE | T1: Tamanho | U1: Desv.Pad. tamanho
A2: Cliente 1 | B2: Vendedor 2 | C2: Móvel | D2: Renovação | E2: 20723972248 | F2: 1459 | G2: 6716 | H2: {=IF(E2:E16531="", "", SUBSTITUTE(SUBSTITUTE(E2:E16531, ".", ""), "-", ""))} -> 20723972248 | I2: {=IF(H2:H16531="", "", IF(ISNUMBER(MATCH(H2:H16531, 'Base de faturamento'!A:A, 0)), 1, 0))} -> 1 | J2: =SUM(I2:I16531) -> 554 | K2: {=IF(A2:A16531="", "", IF(VALUE(I2:I16531)=1, IF(C2:C16531="Móvel", IF(D2:D16531="Novo", VALUE(F2:F16531)*0.3, IF(VALUE(F2:F16531)-VALUE(G2:G16531)>0, (VALUE(F2:F16531)-VALUE(G2:G16531))*0.3, 0)), IF(C2:C16531="Fixa", IF(D2:D16531="Novo", VALUE(F2:F16531)*0.2, IF(VALUE(F2:F16531)-VALUE(G2:G16531)>0, (VALUE(F2:F16531)-VALUE(G2:G16531))*0.2, 0)), 0) ), 0))} -> 0 | L2: =SUM(K2:K16531) -> 514113.6 | M2: =IFERROR(__xludf.DUMMYFUNCTION("ARRAYFORMULA(IF(('Base de vendas'!I2:I16531<>1) + ('Base de vendas'!H2:H16531=""""), """", IFERROR( IF(REGEXMATCH('Base de vendas'!B2:B16531, ""Vendedor 1|Vendedor 2|Vendedor 3""), IF(DAY(VLOOKUP('Base de vendas'!H2:H16531, 'Base de faturamen"&"to'!A:C, 3, 0)) <= 15, EOMONTH(VLOOKUP('Base de vendas'!H2:H16531, 'Base de faturamento'!A:C, 3, 0), -1) + 15, EOMONTH(VLOOKUP('Base de vendas'!H2:H16531, 'Base de faturamento'!A:C, 3, 0), 0) + 15), EOMONTH(VLOOKUP('Base de venda"&"s'!H2:H16531, 'Base de faturamento'!A:C, 3, 0), 0) + 1 ), """") ))"),44696.0) -> 44696 | N2: {=IF(VALUE(I2:I16531)=1, IF(C2:C16531="Móvel", "Backoffice Móvel", "Backoffice Fixa"), "")} -> Backoffice Móvel | O2: {=IF(A2:A16531="", "", IF(N2:N16531<>"", 1, 0))} -> 1 | P2: =SUM(O2:O16531) -> 554 | Q2: {=IF(('Base de vendas'!N2:N16531="") + ('Base de vendas'!H2:H16531=""), "", IFERROR( IF(VLOOKUP('Base de vendas'!H2:H16531, 'Base de faturamento'!A:C, 3, 0)=0, "", EOMONTH(VLOOKUP('Base de vendas'!H2:H16531, 'Base de faturamento'!A:C, 3, 0), 0) + 1), "") )} -> 44713 | T2: {=IF(E2:E16531="","", LENB((SUBSTITUTE(SUBSTITUTE(E2:E16531, ".", ""), "-", ""))))} -> 11 | U2: =STDEV(T2:T16531) -> 0
A3: Cliente 2 | B3: Vendedor 1 | C3: Móvel | D3: Renovação | E3: 27674450597 | F3: 5628 | G3: 1847 | H3: 27674450597 | I3: 1 | K3: 1134.3 | M3: =IFERROR(__xludf.DUMMYFUNCTION("""COMPUTED_VALUE"""),44696.0) -> 44696 | N3: Backoffice Móvel | O3: 1 | Q3: 44682 | T3: 11
A4: Cliente 3 | B4: Vendedor 4 | C4: Móvel | D4: Renovação | E4: 596.733.289-83 | F4: 1138 | G4: 1579 | H4: 59673328983 | I4: 0 | K4: 0 | M4: =IFERROR(__xludf.DUMMYFUNCTION("""COMPUTED_VALUE"""),"") | O4: 0 | T4: 11
A5: Cliente 4 | B5: Vendedor 7 | C5: Móvel | D5: Renovação | E5: 157.209.027-07 | F5: 1146 | G5: 9571 | H5: 15720902707 | I5: 1 | K5: 0 | M5: =IFERROR(__xludf.DUMMYFUNCTION("""COMPUTED_VALUE"""),44713.0) -> 44713 | N5: Backoffice Móvel | O5: 1 | Q5: 44713 | T5: 11
A6: Cliente 5 | B6: Vendedor 5 | C6: Móvel | D6: Renovação | E6: 34321267262 | F6: 2159 | G6: 8912 | H6: 34321267262 | I6: 1 | K6: 0 | M6: =IFERROR(__xludf.DUMMYFUNCTION("""COMPUTED_VALUE"""),44743.0) -> 44743 | N6: Backoffice Móvel | O6: 1 | Q6: 44743 | T6: 11
A7: Cliente 6 | B7: Vendedor 4 | C7: Móvel | D7: Renovação | E7: 196.180.028-10 | F7: 3076 | G7: 6148 | H7: 19618002810 | I7: 0 | K7: 0 | M7: =IFERROR(__xludf.DUMMYFUNCTION("""COMPUTED_VALUE"""),"") | O7: 0 | T7: 11
A8: Cliente 7 | B8: Vendedor 7 | C8: Móvel | D8: Renovação | E8: 436.087.234-05 | F8: 4269 | G8: 3243 | H8: 43608723405 | I8: 1 | K8: 307.8 | M8: =IFERROR(__xludf.DUMMYFUNCTION("""COMPUTED_VALUE"""),44743.0) -> 44743 | N8: Backoffice Móvel | O8: 1 | Q8: 44743 | T8: 11
A9: Cliente 8 | B9: Vendedor 4 | C9: Móvel | D9: Renovação | E9: 983.629.863-93 | F9: 5370 | G9: 1938 | H9: 98362986393 | I9: 1 | K9: 1029.6 | M9: =IFERROR(__xludf.DUMMYFUNCTION("""COMPUTED_VALUE"""),44682.0) -> 44682 | N9: Backoffice Móvel | O9: 1 | Q9: 44682 | T9: 11
A10: Cliente 9 | B10: Vendedor 7 | C10: Móvel | D10: Renovação | E10: 225.448.521-10 | F10: 5336 | G10: 9330 | H10: 22544852110 | I10: 1 | K10: 0 | M10: =IFERROR(__xludf.DUMMYFUNCTION("""COMPUTED_VALUE"""),44682.0) -> 44682 | N10: Backoffice Móvel | O10: 1 | Q10: 44682 | T10: 11
A11: Cliente 10 | B11: Vendedor 6 | C11: Móvel | D11: Renovação | E11: 296.469.719-76 | F11: 3119 | G11: 7499 | H11: 29646971976 | I11: 0 | K11: 0 | M11: =IFERROR(__xludf.DUMMYFUNCTION("""COMPUTED_VALUE"""),"") | O11: 0 | T11: 11
A12: Cliente 11 | B12: Vendedor 4 | C12: Móvel | D12: Renovação | E12: 72642874240 | F12: 8349 | G12: 8525 | H12: 72642874240 | I12: 0 | K12: 0 | M12: =IFERROR(__xludf.DUMMYFUNCTION("""COMPUTED_VALUE"""),"") | O12: 0 | T12: 11
A13: Cliente 12 | B13: Vendedor 1 | C13: Móvel | D13: Renovação | E13: 67563233991 | F13: 7785 | G13: 4881 | H13: 67563233991 | I13: 1 | K13: 871.2 | M13: =IFERROR(__xludf.DUMMYFUNCTION("""COMPUTED_VALUE"""),44727.0) -> 44727 | N13: Backoffice Móvel | O13: 1 | Q13: 44743 | T13: 11
A14: Cliente 13 | B14: Vendedor 8 | C14: Móvel | D14: Renovação | E14: 18175071887 | F14: 8410 | G14: 6035 | H14: 18175071887 | I14: 1 | K14: 712.5 | M14: =IFERROR(__xludf.DUMMYFUNCTION("""COMPUTED_VALUE"""),44652.0) -> 44652 | N14: Backoffice Móvel | O14: 1 | Q14: 44652 | T14: 11
A15: Cliente 14 | B15: Vendedor 8 | C15: Móvel | D15: Renovação | E15: 20503026585 | F15: 5574 | G15: 9950 | H15: 20503026585 | I15: 1 | K15: 0 | M15: =IFERROR(__xludf.DUMMYFUNCTION("""COMPUTED_VALUE"""),44682.0) -> 44682 | N15: Backoffice Móvel | O15: 1 | Q15: 44682 | T15: 11
A16: Cliente 15 | B16: Vendedor 3 | C16: Móvel | D16: Renovação | E16: 57413657804 | F16: 2167 | G16: 1512 | H16: 57413657804 | I16: 1 | K16: 196.5 | M16: =IFERROR(__xludf.DUMMYFUNCTION("""COMPUTED_VALUE"""),44666.0) -> 44666 | N16: Backoffice Móvel | O16: 1 | Q16: 44682 | T16: 11
A17: Cliente 16 | B17: Vendedor 5 | C17: Móvel | D17: Renovação | E17: 426.085.686-18 | F17: 5549 | G17: 2361 | H17: 42608568618 | I17: 1 | K17: 956.4 | M17: =IFERROR(__xludf.DUMMYFUNCTION("""COMPUTED_VALUE"""),44713.0) -> 44713 | N17: Backoffice Móvel | O17: 1 | Q17: 44713 | T17: 11
A18: Cliente 17 | B18: Vendedor 3 | C18: Móvel | D18: Renovação | E18: 56599553971 | F18: 9005 | G18: 8693 | H18: 56599553971 | I18: 0 | K18: 0 | M18: =IFERROR(__xludf.DUMMYFUNCTION("""COMPUTED_VALUE"""),"") | O18: 0 | T18: 11
A19: Cliente 18 | B19: Vendedor 4 | C19: Móvel | D19: Renovação | E19: 619.394.752-16 | F19: 4083 | G19: 4322 | H19: 61939475216 | I19: 1 | K19: 0 | M19: =IFERROR(__xludf.DUMMYFUNCTION("""COMPUTED_VALUE"""),44682.0) -> 44682 | N19: Backoffice Móvel | O19: 1 | Q19: 44682 | T19: 11
A20: Cliente 19 | B20: Vendedor 7 | C20: Móvel | D20: Renovação | E20: 373.517.410-26 | F20: 9289 | G20: 2239 | H20: 37351741026 | I20: 0 | K20: 0 | M20: =IFERROR(__xludf.DUMMYFUNCTION("""COMPUTED_VALUE"""),"") | O20: 0 | T20: 11
A21: Cliente 20 | B21: Vendedor 7 | C21: Móvel | D21: Renovação | E21: 593.243.931-16 | F21: 1040 | G21: 6374 | H21: 59324393116 | I21: 1 | K21: 0 | M21: =IFERROR(__xludf.DUMMYFUNCTION("""COMPUTED_VALUE"""),44713.0) -> 44713 | N21: Backoffice Móvel | O21: 1 | Q21: 44713 | T21: 11
A22: Cliente 21 | B22: Vendedor 8 | C22: Móvel | D22: Renovação | E22: 999.543.040-75 | F22: 1716 | G22: 2809 | H22: 99954304075 | I22: 1 | K22: 0 | M22: =IFERROR(__xludf.DUMMYFUNCTION("""COMPUTED_VALUE"""),44682.0) -> 44682 | N22: Backoffice Móvel | O22: 1 | Q22: 44682 | T22: 11
A23: Cliente 22 | B23: Vendedor 7 | C23: Móvel | D23: Renovação | E23: 44783399451 | F23: 6702 | G23: 2525 | H23: 44783399451 | I23: 0 | K23: 0 | M23: =IFERROR(__xludf.DUMMYFUNCTION("""COMPUTED_VALUE"""),"") | O23: 0 | T23: 11
A24: Cliente 23 | B24: Vendedor 2 | C24: Móvel | D24: Renovação | E24: 91230368786 | F24: 9375 | G24: 3237 | H24: 91230368786 | I24: 1 | K24: 1841.4 | M24: =IFERROR(__xludf.DUMMYFUNCTION("""COMPUTED_VALUE"""),44757.0) -> 44757 | N24: Backoffice Móvel | O24: 1 | Q24: 44743 | T24: 11
A25: Cliente 24 | B25: Vendedor 3 | C25: Móvel | D25: Renovação | E25: 15765206124 | F25: 1254 | G25: 6922 | H25: 15765206124 | I25: 0 | K25: 0 | M25: =IFERROR(__xludf.DUMMYFUNCTION("""COMPUTED_VALUE"""),"") | O25: 0 | T25: 11
A26: Cliente 25 | B26: Vendedor 7 | C26: Móvel | D26: Renovação | E26: 294.933.876-36 | F26: 4504 | G26: 6773 | H26: 29493387636 | I26: 0 | K26: 0 | M26: =IFERROR(__xludf.DUMMYFUNCTION("""COMPUTED_VALUE"""),"") | O26: 0 | T26: 11
A27: Cliente 26 | B27: Vendedor 5 | C27: Móvel | D27: Renovação | E27: 839.697.221-44 | F27: 6997 | G27: 2338 | H27: 83969722144 | I27: 1 | K27: 1397.7 | M27: =IFERROR(__xludf.DUMMYFUNCTION("""COMPUTED_VALUE"""),44682.0) -> 44682 | N27: Backoffice Móvel | O27: 1 | Q27: 44682 | T27: 11
A28: Cliente 27 | B28: Vendedor 3 | C28: Móvel | D28: Renovação | E28: 38621453271 | F28: 9645 | G28: 5274 | H28: 38621453271 | I28: 1 | K28: 1311.3 | M28: =IFERROR(__xludf.DUMMYFUNCTION("""COMPUTED_VALUE"""),44635.0) -> 44635 | N28: Backoffice Móvel | O28: 1 | Q28: 44652 | T28: 11
A29: Cliente 28 | B29: Vendedor 3 | C29: Móvel | D29: Renovação | E29: 669.536.990-20 | F29: 9568 | G29: 6538 | H29: 66953699020 | I29: 1 | K29: 909 | M29: =IFERROR(__xludf.DUMMYFUNCTION("""COMPUTED_VALUE"""),44635.0) -> 44635 | N29: Backoffice Móvel | O29: 1 | Q29: 44652 | T29: 11
A30: Cliente 29 | B30: Vendedor 8 | C30: Móvel | D30: Renovação | E30: 998.547.899-40 | F30: 3121 | G30: 6461 | H30: 99854789940 | I30: 1 | K30: 0 | M30: =IFERROR(__xludf.DUMMYFUNCTION("""COMPUTED_VALUE"""),44743.0) -> 44743 | N30: Backoffice Móvel | O30: 1 | Q30: 44743 | T30: 11
A31: Cliente 30 | B31: Vendedor 5 | C31: Móvel | D31: Renovação | E31: 773.527.620-84 | F31: 6600 | G31: 4573 | H31: 77352762084 | I31: 0 | K31: 0 | M31: =IFERROR(__xludf.DUMMYFUNCTION("""COMPUTED_VALUE"""),"") | O31: 0 | T31: 11
A32: Cliente 31 | B32: Vendedor 1 | C32: Móvel | D32: Renovação | E32: 352.786.454-67 | F32: 5522 | G32: 6243 | H32: 35278645467 | I32: 1 | K32: 0 | M32: =IFERROR(__xludf.DUMMYFUNCTION("""COMPUTED_VALUE"""),44666.0) -> 44666 | N32: Backoffice Móvel | O32: 1 | Q32: 44682 | T32: 11
A33: Cliente 32 | B33: Vendedor 5 | C33: Móvel | D33: Renovação | E33: 436.999.748-83 | F33: 8844 | G33: 6170 | H33: 43699974883 | I33: 0 | K33: 0 | M33: =IFERROR(__xludf.DUMMYFUNCTION("""COMPUTED_VALUE"""),"") | O33: 0 | T33: 11
A34: Cliente 33 | B34: Vendedor 7 | C34: Móvel | D34: Renovação | E34: 849.910.131-72 | F34: 2920 | G34: 4510 | H34: 84991013172 | I34: 1 | K34: 0 | M34: =IFERROR(__xludf.DUMMYFUNCTION("""COMPUTED_VALUE"""),44682.0) -> 44682 | N34: Backoffice Móvel | O34: 1 | Q34: 44682 | T34: 11
A35: Cliente 34 | B35: Vendedor 4 | C35: Móvel | D35: Renovação | E35: 88355096302 | F35: 5208 | G35: 2383 | H35: 88355096302 | I35: 0 | K35: 0 | M35: =IFERROR(__xludf.DUMMYFUNCTION("""COMPUTED_VALUE"""),"") | O35: 0 | T35: 11
A36: Cliente 35 | B36: Vendedor 5 | C36: Móvel | D36: Renovação | E36: 832.509.802-94 | F36: 7819 | G36: 1004 | H36: 83250980294 | I36: 1 | K36: 2044.5 | M36: =IFERROR(__xludf.DUMMYFUNCTION("""COMPUTED_VALUE"""),44743.0) -> 44743 | N36: Backoffice Móvel | O36: 1 | Q36: 44743 | T36: 11
A37: Cliente 36 | B37: Vendedor 1 | C37: Móvel | D37: Renovação | E37: 50846615899 | F37: 5217 | G37: 2024 | H37: 50846615899 | I37: 1 | K37: 957.9 | M37: =IFERROR(__xludf.DUMMYFUNCTION("""COMPUTED_VALUE"""),44696.0) -> 44696 | N37: Backoffice Móvel | O37: 1 | Q37: 44682 | T37: 11
A38: Cliente 37 | B38: Vendedor 7 | C38: Móvel | D38: Renovação | E38: 531.576.575-24 | F38: 1899 | G38: 2987 | H38: 53157657524 | I38: 1 | K38: 0 | M38: =IFERROR(__xludf.DUMMYFUNCTION("""COMPUTED_VALUE"""),44652.0) -> 44652 | N38: Backoffice Móvel | O38: 1 | Q38: 44652 | T38: 11
A39: Cliente 38 | B39: Vendedor 3 | C39: Móvel | D39: Renovação | E39: 75252280913 | F39: 1242 | G39: 3588 | H39: 75252280913 | I39: 1 | K39: 0 | M39: =IFERROR(__xludf.DUMMYFUNCTION("""COMPUTED_VALUE"""),44666.0) -> 44666 | N39: Backoffice Móvel | O39: 1 | Q39: 44652 | T39: 11
A40: Cliente 39 | B40: Vendedor 4 | C40: Móvel | D40: Renovação | E40: 12766025437 | F40: 8941 | G40: 4282 | H40: 12766025437 | I40: 1 | K40: 1397.7 | M40: =IFERROR(__xludf.DUMMYFUNCTION("""COMPUTED_VALUE"""),44743.0) -> 44743 | N40: Backoffice Móvel | O40: 1 | Q40: 44743 | T40: 11
...

Sheet Base de faturamento
A1: Número de série da venda | B1: Valor faturado | C1: Data de pagamento
A2: 20723972248 | B2: 1459 | C2: 44686
A3: 27674450597 | B3: 5628 | C3: 44674
A4: 15720902707 | B4: 1146 | C4: 44688
A5: 34321267262 | B5: 2159 | C5: 44721
A6: 43608723405 | B6: 4269 | C6: 44734
A7: 98362986393 | B7: 5370 | C7: 44654
A8: 22544852110 | B8: 5336 | C8: 44670
A9: 67563233991 | B9: 7785 | C9: 44722
A10: 18175071887 | B10: 8410 | C10: 44642
A11: 20503026585 | B11: 5574 | C11: 44680
A12: 57413657804 | B12: 2167 | C12: 44656
A13: 42608568618 | B13: 5549 | C13: 44705
... A555: 71897943376 | B555: 2970 | C555: 44711

Sheet Dados
A1: Vendedor | B1: Comissão dos vendedores (R$) | G1: Backoffice | H1: Comissão | M1: Time | N1: Comissão | S1: DATA DE PAGAMENTO | T1: Vendedor 1 | U1: Vendedor 2 | V1: Vendedor 3 | W1: Vendedor 4 | X1: Vendedor 5 | Y1: Vendedor 6 | Z1: Vendedor 7 | AA1: Vendedor 8 | AB1: Backoffice Móvel | AC1: Backoffice Fixa | AD1: Orçamento do dia a ser pago
A2: Vendedor 1 | B2: {=SUMIF('Base de vendas'!B2:B1000, "Vendedor " & {1;2;3;4;5;6;7;8}, 'Base de vendas'!K2:K1000)} -> 73017.2 | G2: Móvel | H2: {=COUNTIFS('Base de vendas'!N2:N1000, {"Backoffice Móvel"; "Backoffice Fixa"})} -> 253 | M2: Time 1 | N2: =SUM(B2:B4) -> 194402.6 | S2: {=SORT(UNIQUE('Base de vendas'!M2:M1000))} -> 44635 | T2: {=IF(S2:S1000="", "", SUMIF('Base de vendas'!B:B & 'Base de vendas'!M:M, "Vendedor 1" & S2:S1000, 'Base de vendas'!K:K))} -> 10325.1 | U2: {=IF($S2:$S1000="", "", SUMIF('Base de vendas'!$B:$B & 'Base de vendas'!$M:$M, U1:AA1 & $S2:$S1000, 'Base de vendas'!$K:$K))} -> 13942.1 | V2: 20799.8 | W2: 0 | X2: 0 | Y2: 0 | Z2: 0 | AA2: 0 | AB2: {=IF(S2:S1000="", "", COUNTIFS('Base de vendas'!N2:N1000, "Backoffice Móvel", 'Base de vendas'!Q2:Q1000, S2:S1000))} -> 0 | AC2: {=IF(S2:S1000="", "", COUNTIFS('Base de vendas'!N2:N1000, "Backoffice Fixa", 'Base de vendas'!Q2:Q1000, S2:S1000))} -> 0 | AD2: {=IF(S2:S1000="", "", MMULT(N(T2:AC1000), SEQUENCE(COLUMNS(T2:AC1000), 1, 1, 0)))} -> 45067
A3: Vendedor 2 | B3: 58981.7 | G3: Fixa | H3: 301 | M3: Time 2 | N3: =SUM(B5:B7) -> 190967 | S3: 44652 | T3: 0 | U3: 0 | V3: 0 | W3: 24577.6 | X3: 16893 | Y3: 15052 | Z3: 16706.7 | AA3: 8637.1 | AB3: 63 | AC3: 79 | AD3: 82008.4
A4: Vendedor 3 | B4: 62403.7 | G4: TOTAL(R$) | H4: =SUM(H2:H3) -> 554 | M4: Time 3 | N4: =SUM(B8:B9) -> 128744 | S4: 44666 | T4: 9194.1 | U4: 15226.1 | V4: 18710.5 | W4: 0 | X4: 0 | Y4: 0 | Z4: 0 | AA4: 0 | AB4: 0 | AC4: 0 | AD4: 43130.7
A5: Vendedor 4 | B5: 68478 | M5: TOTAL (R$) | N5: =SUM(N2:N4) -> 514113.6 | S5: 44682 | T5: 0 | U5: 0 | V5: 0 | W5: 15873.5 | X5: 15412 | Y5: 12530.3 | Z5: 14916.4 | AA5: 13357.6 | AB5: 65 | AC5: 76 | AD5: 72230.8
A6: Vendedor 5 | B6: 72464.7 | S6: 44696 | T6: 18521.5 | U6: 12036.6 | V6: 10149.9 | W6: 0 | X6: 0 | Y6: 0 | Z6: 0 | AA6: 0 | AB6: 0 | AC6: 0 | AD6: 40708
A7: Vendedor 6 | B7: 50024.3 | S7: 44713 | T7: 0 | U7: 0 | V7: 0 | W7: 19531.2 | X7: 17776.3 | Y7: 10262.9 | Z7: 26107.8 | AA7: 15236.4 | AB7: 67 | AC7: 70 | AD7: 89051.6
A8: Vendedor 7 | B8: 74508.8 | S8: 44727 | T8: 26816.9 | U8: 12165.3 | V8: 5542.8 | W8: 0 | X8: 0 | Y8: 0 | Z8: 0 | AA8: 0 | AB8: 0 | AC8: 0 | AD8: 44525
A9: Vendedor 8 | B9: 54235.2 | S9: 44743 | T9: 0 | U9: 0 | V9: 0 | W9: 6556.7 | X9: 22383.4 | Y9: 12179.1 | Z9: 16777.9 | AA9: 17004.1 | AB9: 58 | AC9: 74 | AD9: 75033.2
A10: TOTAL (R$) | B10: =SUM(B2:B9) -> 514113.6 | S10: 44757 | T10: 8159.6 | U10: 5611.6 | V10: 7200.7 | W10: 0 | X10: 0 | Y10: 0 | Z10: 0 | AA10: 0 | AB10: 0 | AC10: 0 | AD10: 20971.9
S11: 44774 | T11: 0 | U11: 0 | V11: 0 | W11: 1939 | X11: 0 | Y11: 0 | Z11: 0 | AA11: 0 | AB11: 0 | AC11: 2 | AD11: 1941
